Workbook

Sheet START HERE
A1: Synthetic cachexia simulation workbook
A2: Interactive, macro-free clinical review prototype.
A4: NOT FOR CLINICAL USE. All patients and outputs are synthetic. Category relationships are simulation assumptions, not clinically validated effects. Do not use for diagnosis, prognosis, treatment, patient care, or medical decisions.
A8: Step | B8: Action
A9: 1 | B9: Open Calculator and change only blue input cells.
A10: 2 | B10: Enter an explicit prediction date and dated weight history.
A11: 3 | B11: Open Results to inspect baseline-derived status and separate illustrative simulation categories.
A12: 4 | B12: Review Assumptions before interpreting any output; every relationship is provisional.
A13: 5 | B13: Use Clinical Review to record decisions and requested changes.
A16: Compatibility | B16: Excel 2019 or Microsoft 365. Formulas recalculate when the workbook opens.
A18: Statistical testing | B18: No clinical hypothesis testing is claimed. The current tests verify calculation, temporal, boundary, missingness, reproducibility, and configuration behavior only.
A21: Implemented cachexia criteria | B21: Baseline-derived current criteria status uses >5% retrospective loss or >2% loss with BMI <20 kg/m². For >2% and <=5% loss with BMI >=20, status remains unknown while the sarcopenia branch is disabled pending a clinical definition.
A23: Provisional early-risk pattern | B23: After cachexia criteria are excluded: weight loss >1% and <=5% plus baseline reduced appetite=yes. The >1% bound has no consensus basis; <=5% is consensus-aligned; binary appetite is a POC simplification.

Sheet Calculator
A1: Interactive synthetic patient input
A2: Change blue cells, then review automatically recalculated outputs on Results.
A4: NOT FOR CLINICAL USE. All patients and outputs are synthetic. Category relationships are simulation assumptions, not clinically validated effects. Do not use for diagnosis, prognosis, treatment, patient care, or medical decisions.
A6: Eligibility and inclusion criteria are not yet defined. Cancer-type labels are synthetic stratifiers for an adult solid-tumour POC pending clinical review.
A8: Prediction date | B8: 46053 | G8: Baseline-derived status and illustrative categories
A9: Age (years) | B9: 65 | G9: Baseline/current weight | H9: ='Results'!B9 | J9: 3-month illustrative simulation category | K9: ='Results'!B25
A10: Sex (descriptive; unused in category) | B10: female | G10: BMI | H10: ='Results'!B12 | J10: Basis / status | K10: ='Results'!B26
A11: Cancer type (synthetic stratifier) | B11: lung | G11: Weight loss | H11: ='Results'!B13 | J11: Explanation | K11: ='Results'!B27
A12: Lung subtype (descriptive; unused) | B12: NSCLC | G12: Interval | H12: ='Results'!B14 | J12: Target outcome | K12: Target outcome is not defined pending clinical review.
A13: Cancer stage | B13: III | G13: Weight-loss rate | H13: ='Results'!B15 | J13: 6-month illustrative simulation category | K13: ='Results'!D25
A14: Height (cm; optional, required for BMI/category) | B14: 170 | G14: Trajectory | H14: ='Results'!B17 | J14: Basis / status | K14: ='Results'!D26
A15: ECOG | B15: 2 | J15: Explanation | K15: ='Results'!D27
A16: Reduced appetite | B16: no | G16: Current cachexia criteria status | H16: ='Results'!B19 | J16: Target outcome | K16: Target outcome is not defined pending clinical review.
A17: Sarcopenia (future-use; unused in v1) | B17: unknown | G17: Current provisional pre-cachexia candidate | H17: ='Results'!B20
A20: Dated weight history (predictors use only dates <= prediction date) | G20: Rules shown in plain language Baseline-derived cachexia criteria status: >5% retrospective weight loss, or >2% loss with BMI <20 kg/m². For loss >2% and <=5% with BMI >=20, status is unknown because the sarcopenia branch is disabled pending a clinical definition. Provisional pre-cachexia candidate: cachexia criteria not met, >1% and <=5% loss, and baseline reduced appetite=yes. The >1% lower bound has no consensus basis and is editable; <=5% is consensus-aligned. Binary appetite is a POC simplification.
A21: Measurement date | B21: Weight (kg) | C21: Baseline candidate | D21: Prior candidate | E21: Eligibility note
A22: 45869 | B22: 80 | C22: =IF(AND(ISNUMBER(A22),ISNUMBER(B22),A22<=$B$8,B22>='Assumptions'!$B$18,B22<='Assumptions'!$B$19),A22,0) | D22: =IF(AND(ISNUMBER(A22),ISNUMBER(B22),'Results'!$B$8<>"",A22<'Results'!$B$8,A22>=EDATE('Results'!$B$8,-6),B22>='Assumptions'!$B$18,B22<='Assumptions'!$B$19),A22,DATE(9999,12,31)) | E22: =IF(OR(A22="",B22=""),"incomplete / ignored",IF(A22<=$B$8,"baseline-eligible","outcome-only / excluded from predictors"))
A23: 46053 | B23: 76 | C23: =IF(AND(ISNUMBER(A23),ISNUMBER(B23),A23<=$B$8,B23>='Assumptions'!$B$18,B23<='Assumptions'!$B$19),A23,0) | D23: =IF(AND(ISNUMBER(A23),ISNUMBER(B23),'Results'!$B$8<>"",A23<'Results'!$B$8,A23>=EDATE('Results'!$B$8,-6),B23>='Assumptions'!$B$18,B23<='Assumptions'!$B$19),A23,DATE(9999,12,31)) | E23: =IF(OR(A23="",B23=""),"incomplete / ignored",IF(A23<=$B$8,"baseline-eligible","outcome-only / excluded from predictors"))
C24: =IF(AND(ISNUMBER(A24),ISNUMBER(B24),A24<=$B$8,B24>='Assumptions'!$B$18,B24<='Assumptions'!$B$19),A24,0) | D24: =IF(AND(ISNUMBER(A24),ISNUMBER(B24),'Results'!$B$8<>"",A24<'Results'!$B$8,A24>=EDATE('Results'!$B$8,-6),B24>='Assumptions'!$B$18,B24<='Assumptions'!$B$19),A24,DATE(9999,12,31)) | E24: =IF(OR(A24="",B24=""),"incomplete / ignored",IF(A24<=$B$8,"baseline-eligible","outcome-only / excluded from predictors"))
C25: =IF(AND(ISNUMBER(A25),ISNUMBER(B25),A25<=$B$8,B25>='Assumptions'!$B$18,B25<='Assumptions'!$B$19),A25,0) | D25: =IF(AND(ISNUMBER(A25),ISNUMBER(B25),'Results'!$B$8<>"",A25<'Results'!$B$8,A25>=EDATE('Results'!$B$8,-6),B25>='Assumptions'!$B$18,B25<='Assumptions'!$B$19),A25,DATE(9999,12,31)) | E25: =IF(OR(A25="",B25=""),"incomplete / ignored",IF(A25<=$B$8,"baseline-eligible","outcome-only / excluded from predictors"))
C26: =IF(AND(ISNUMBER(A26),ISNUMBER(B26),A26<=$B$8,B26>='Assumptions'!$B$18,B26<='Assumptions'!$B$19),A26,0) | D26: =IF(AND(ISNUMBER(A26),ISNUMBER(B26),'Results'!$B$8<>"",A26<'Results'!$B$8,A26>=EDATE('Results'!$B$8,-6),B26>='Assumptions'!$B$18,B26<='Assumptions'!$B$19),A26,DATE(9999,12,31)) | E26: =IF(OR(A26="",B26=""),"incomplete / ignored",IF(A26<=$B$8,"baseline-eligible","outcome-only / excluded from predictors"))
C27: =IF(AND(ISNUMBER(A27),ISNUMBER(B27),A27<=$B$8,B27>='Assumptions'!$B$18,B27<='Assumptions'!$B$19),A27,0) | D27: =IF(AND(ISNUMBER(A27),ISNUMBER(B27),'Results'!$B$8<>"",A27<'Results'!$B$8,A27>=EDATE('Results'!$B$8,-6),B27>='Assumptions'!$B$18,B27<='Assumptions'!$B$19),A27,DATE(9999,12,31)) | E27: =IF(OR(A27="",B27=""),"incomplete / ignored",IF(A27<=$B$8,"baseline-eligible","outcome-only / excluded from predictors"))
C28: =IF(AND(ISNUMBER(A28),ISNUMBER(B28),A28<=$B$8,B28>='Assumptions'!$B$18,B28<='Assumptions'!$B$19),A28,0) | D28: =IF(AND(ISNUMBER(A28),ISNUMBER(B28),'Results'!$B$8<>"",A28<'Results'!$B$8,A28>=EDATE('Results'!$B$8,-6),B28>='Assumptions'!$B$18,B28<='Assumptions'!$B$19),A28,DATE(9999,12,31)) | E28: =IF(OR(A28="",B28=""),"incomplete / ignored",IF(A28<=$B$8,"baseline-eligible","outcome-only / excluded from predictors"))
C29: =IF(AND(ISNUMBER(A29),ISNUMBER(B29),A29<=$B$8,B29>='Assumptions'!$B$18,B29<='Assumptions'!$B$19),A29,0) | D29: =IF(AND(ISNUMBER(A29),ISNUMBER(B29),'Results'!$B$8<>"",A29<'Results'!$B$8,A29>=EDATE('Results'!$B$8,-6),B29>='Assumptions'!$B$18,B29<='Assumptions'!$B$19),A29,DATE(9999,12,31)) | E29: =IF(OR(A29="",B29=""),"incomplete / ignored",IF(A29<=$B$8,"baseline-eligible","outcome-only / excluded from predictors"))
C30: =IF(AND(ISNUMBER(A30),ISNUMBER(B30),A30<=$B$8,B30>='Assumptions'!$B$18,B30<='Assumptions'!$B$19),A30,0) | D30: =IF(AND(ISNUMBER(A30),ISNUMBER(B30),'Results'!$B$8<>"",A30<'Results'!$B$8,A30>=EDATE('Results'!$B$8,-6),B30>='Assumptions'!$B$18,B30<='Assumptions'!$B$19),A30,DATE(9999,12,31)) | E30: =IF(OR(A30="",B30=""),"incomplete / ignored",IF(A30<=$B$8,"baseline-eligible","outcome-only / excluded from predictors"))
C31: =IF(AND(ISNUMBER(A31),ISNUMBER(B31),A31<=$B$8,B31>='Assumptions'!$B$18,B31<='Assumptions'!$B$19),A31,0) | D31: =IF(AND(ISNUMBER(A31),ISNUMBER(B31),'Results'!$B$8<>"",A31<'Results'!$B$8,A31>=EDATE('Results'!$B$8,-6),B31>='Assumptions'!$B$18,B31<='Assumptions'!$B$19),A31,DATE(9999,12,31)) | E31: =IF(OR(A31="",B31=""),"incomplete / ignored",IF(A31<=$B$8,"baseline-eligible","outcome-only / excluded from predictors"))
C32: =IF(AND(ISNUMBER(A32),ISNUMBER(B32),A32<=$B$8,B32>='Assumptions'!$B$18,B32<='Assumptions'!$B$19),A32,0) | D32: =IF(AND(ISNUMBER(A32),ISNUMBER(B32),'Results'!$B$8<>"",A32<'Results'!$B$8,A32>=EDATE('Results'!$B$8,-6),B32>='Assumptions'!$B$18,B32<='Assumptions'!$B$19),A32,DATE(9999,12,31)) | E32: =IF(OR(A32="",B32=""),"incomplete / ignored",IF(A32<=$B$8,"baseline-eligible","outcome-only / excluded from predictors"))
C33: =IF(AND(ISNUMBER(A33),ISNUMBER(B33),A33<=$B$8,B33>='Assumptions'!$B$18,B33<='Assumptions'!$B$19),A33,0) | D33: =IF(AND(ISNUMBER(A33),ISNUMBER(B33),'Results'!$B$8<>"",A33<'Results'!$B$8,A33>=EDATE('Results'!$B$8,-6),B33>='Assumptions'!$B$18,B33<='Assumptions'!$B$19),A33,DATE(9999,12,31)) | E33: =IF(OR(A33="",B33=""),"incomplete / ignored",IF(A33<=$B$8,"baseline-eligible","outcome-only / excluded from predictors"))

Sheet Results
A1: Calculated synthetic outputs
A2: Excel 2019 / Microsoft 365 formulas. Blank means not calculable; unknown is not no.
A4: NOT FOR CLINICAL USE. All patients and outputs are synthetic. Category relationships are simulation assumptions, not clinically validated effects. Do not use for diagnosis, prognosis, treatment, patient care, or medical decisions.
A8: Baseline weight date | B8: =IF(MAX('Calculator'!$C$22:$C$33)=0,"",MAX('Calculator'!$C$22:$C$33))
A9: Baseline/current weight (kg) | B9: =IF(B8="","",IF(COUNTIFS('Calculator'!$A$22:$A$33,B8,'Calculator'!$B$22:$B$33,">="&'Assumptions'!$B$18,'Calculator'!$B$22:$B$33,"<="&'Assumptions'!$B$19)<>1,"",SUMIFS('Calculator'!$B$22:$B$33,'Calculator'!$A$22:$A$33,B8,'Calculator'!$B$22:$B$33,">="&'Assumptions'!$B$18,'Calculator'!$B$22:$B$33,"<="&'Assumptions'!$B$19)))
A10: Prior comparison date | B10: =IF(OR(B8="",MIN('Calculator'!$D$22:$D$33)=DATE(9999,12,31)),"",MIN('Calculator'!$D$22:$D$33))
A11: Prior comparison weight (kg) | B11: =IF(B10="","",IF(COUNTIFS('Calculator'!$A$22:$A$33,B10,'Calculator'!$B$22:$B$33,">="&'Assumptions'!$B$18,'Calculator'!$B$22:$B$33,"<="&'Assumptions'!$B$19)<>1,"",SUMIFS('Calculator'!$B$22:$B$33,'Calculator'!$A$22:$A$33,B10,'Calculator'!$B$22:$B$33,">="&'Assumptions'!$B$18,'Calculator'!$B$22:$B$33,"<="&'Assumptions'!$B$19)))
A12: BMI (kg/m²) | B12: =IF(OR(B9="",'Calculator'!B14=""),"",B9/('Calculator'!B14/100)^2)
A13: Percentage weight loss (+ = loss) | B13: =IF(OR(B9="",B11=""),"",((B11-B9)/B11)*100)
A14: Interval (days) | B14: =IF(OR(B8="",B10=""),"",B8-B10)
A15: Weight-loss rate (kg/month) | B15: =IF(OR(B9="",B11="",B14<=0),"",(B11-B9)/(B14/'Assumptions'!$B$8))
A16: Rate (percentage points/month) | B16: =IF(OR(B13="",B14<=0),"",B13/(B14/'Assumptions'!$B$8))
A17: Trajectory | B17: =IF(B13="","unknown",IF(B13>'Assumptions'!$B$9,"loss",IF(B13<-'Assumptions'!$B$9,"gain","stable")))
A19: Current cachexia criteria status | B19: =IF(B13="","unknown",IF(B13>'Assumptions'!$B$10,"yes",IF(B13<='Assumptions'!$B$11,"no",IF(B12="","unknown",IF(B12<'Assumptions'!$B$12,"yes","unknown")))))
A20: Current provisional pre-cachexia candidate | B20: =IF(B19="unknown","unknown",IF(B19="yes","no",IF(OR(B13<='Assumptions'!$B$13,B13>'Assumptions'!$B$14),"no",IF('Calculator'!B16="yes","yes",IF('Calculator'!B16="no","no","unknown")))))
A23: Illustrative simulation horizon | B23: 3 months | D23: 6 months
A24: Output type | B24: illustrative simulation category | D24: illustrative simulation category
A25: Category | B25: =IF(OR('Calculator'!B13="unknown",'Calculator'!B15="unknown",'Calculator'!B16="unknown",B12="",B13=""),"withheld",IF('Assumptions'!$B$20+IF('Calculator'!B9>'Assumptions'!$B$15,'Assumptions'!$B$21,0)+VLOOKUP('Calculator'!B13,'Assumptions'!$H$8:$J$12,2,FALSE)+VLOOKUP('Calculator'!B15,'Assumptions'!$L$8:$N$13,2,FALSE)+VLOOKUP('Calculator'!B16,'Assumptions'!$P$8:$R$10,2,FALSE)+MAX(0,N(B13))*'Assumptions'!$B$22+IF(AND(B12<>"",B12<'Assumptions'!$B$12),'Assumptions'!$B$23,0)+(VLOOKUP('Calculator'!B11,'Assumptions'!$E$8:$F$17,2,FALSE)-1)*'Assumptions'!$B$24<'Assumptions'!$B$16,"low",IF('Assumptions'!$B$20+IF('Calculator'!B9>'Assumptions'!$B$15,'Assumptions'!$B$21,0)+VLOOKUP('Calculator'!B13,'Assumptions'!$H$8:$J$12,2,FALSE)+VLOOKUP('Calculator'!B15,'Assumptions'!$L$8:$N$13,2,FALSE)+VLOOKUP('Calculator'!B16,'Assumptions'!$P$8:$R$10,2,FALSE)+MAX(0,N(B13))*'Assumptions'!$B$22+IF(AND(B12<>"",B12<'Assumptions'!$B$12),'Assumptions'!$B$23,0)+(VLOOKUP('Calculator'!B11,'Assumptions'!$E$8:$F$17,2,FALSE)-1)*'Assumptions'!$B$24>='Assumptions'!$B$17,"high","moderate"))) | D25: =IF(OR('Calculator'!B13="unknown",'Calculator'!B15="unknown",'Calculator'!B16="unknown",B12="",B13=""),"withheld",IF('Assumptions'!$B$25+IF('Calculator'!B9>'Assumptions'!$B$15,'Assumptions'!$B$26,0)+VLOOKUP('Calculator'!B13,'Assumptions'!$H$8:$J$12,3,FALSE)+VLOOKUP('Calculator'!B15,'Assumptions'!$L$8:$N$13,3,FALSE)+VLOOKUP('Calculator'!B16,'Assumptions'!$P$8:$R$10,3,FALSE)+MAX(0,N(B13))*'Assumptions'!$B$27+IF(AND(B12<>"",B12<'Assumptions'!$B$12),'Assumptions'!$B$28,0)+(VLOOKUP('Calculator'!B11,'Assumptions'!$E$8:$F$17,2,FALSE)-1)*'Assumptions'!$B$29<'Assumptions'!$B$16,"low",IF('Assumptions'!$B$25+IF('Calculator'!B9>'Assumptions'!$B$15,'Assumptions'!$B$26,0)+VLOOKUP('Calculator'!B13,'Assumptions'!$H$8:$J$12,3,FALSE)+VLOOKUP('Calculator'!B15,'Assumptions'!$L$8:$N$13,3,FALSE)+VLOOKUP('Calculator'!B16,'Assumptions'!$P$8:$R$10,3,FALSE)+MAX(0,N(B13))*'Assumptions'!$B$27+IF(AND(B12<>"",B12<'Assumptions'!$B$12),'Assumptions'!$B$28,0)+(VLOOKUP('Calculator'!B11,'Assumptions'!$E$8:$F$17,2,FALSE)-1)*'Assumptions'!$B$29>='Assumptions'!$B$17,"high","moderate")))
A26: Basis / status | B26: =IF(B25="withheld","Illustrative simulation category; withheld missing required baseline predictors. Target outcome is not defined pending clinical review.","Illustrative simulation category; baseline predictors only; research-only. Target outcome is not defined pending clinical review.") | D26: =IF(D25="withheld","Illustrative simulation category; withheld missing required baseline predictors. Target outcome is not defined pending clinical review.","Illustrative simulation category; baseline predictors only; research-only. Target outcome is not defined pending clinical review.")
A27: Explanation | B27: =IF(OR('Calculator'!B13="unknown",'Calculator'!B15="unknown",'Calculator'!B16="unknown",B12="",B13=""),"Illustrative simulation category withheld: "&IF('Calculator'!B13="unknown","cancer stage is unknown; ","")&IF('Calculator'!B15="unknown","baseline ECOG is unknown; ","")&IF('Calculator'!B16="unknown","baseline reduced appetite is unknown; ","")&IF(B12="","BMI is unavailable because height or baseline weight is unavailable; ","")&IF(B13="","baseline weight change is unavailable because eligible prior history is insufficient; ",""),TRIM(IF('Calculator'!B9>'Assumptions'!$B$15,"age >55; ","")&IF(B13>0,"baseline loss "&TEXT(B13,"0.0")&"%; ","")&IF(AND(B12<>"",B12<'Assumptions'!$B$12),"BMI <20; ","")&"stage "&'Calculator'!B13&"; ECOG "&'Calculator'!B15&"; appetite="&'Calculator'!B16&"; "&'Calculator'!B11)) | D27: =IF(OR('Calculator'!B13="unknown",'Calculator'!B15="unknown",'Calculator'!B16="unknown",B12="",B13=""),"Illustrative simulation category withheld: "&IF('Calculator'!B13="unknown","cancer stage is unknown; ","")&IF('Calculator'!B15="unknown","baseline ECOG is unknown; ","")&IF('Calculator'!B16="unknown","baseline reduced appetite is unknown; ","")&IF(B12="","BMI is unavailable because height or baseline weight is unavailable; ","")&IF(B13="","baseline weight change is unavailable because eligible prior history is insufficient; ",""),TRIM(IF('Calculator'!B9>'Assumptions'!$B$15,"age >55; ","")&IF(B13>0,"baseline loss "&TEXT(B13,"0.0")&"%; ","")&IF(AND(B12<>"",B12<'Assumptions'!$B$12),"BMI <20; ","")&"stage "&'Calculator'!B13&"; ECOG "&'Calculator'!B15&"; appetite="&'Calculator'!B16&"; "&'Calculator'!B11))
A29: Interpretation | B29: These are ordinal illustrative simulation categories based on baseline predictors only. Target outcome is not defined pending clinical review. Differences between horizon categories are simulation assumptions, not different clinically defined estimands. Changing six-month assumptions does not change the three-month formula.

Sheet Assumptions
A1: Central simulation assumptions
A2: Editable for research scenarios only. Values are not validated clinical effects.
A4: NOT FOR CLINICAL USE. All patients and outputs are synthetic. Category relationships are simulation assumptions, not clinically validated effects. Do not use for diagnosis, prognosis, treatment, patient care, or medical decisions.
A6: Key | B6: Value | C6: Status / source
E7: Cancer type | F7: Illustrative multiplier | H7: Stage | I7: 3m term | J7: 6m term | L7: ECOG | M7: 3m term | N7: 6m term | P7: Appetite | Q7: 3m term | R7: 6m term
A8: DaysPerMonth | B8: 30.4375 | C8: Operational normalization | E8: lung | F8: 1.6 | H8: I | I8: 0 | J8: 0 | L8: 0 | M8: -0.3 | N8: -0.25 | P8: yes | Q8: 0.75 | R8: 0.8 | T8: SCLC | U8: not applicable
A9: TrajectoryEpsilon | B9: 0.5 | C9: Simulation assumption | E9: colorectal | F9: 1.3 | H9: II | I9: 0.2 | J9: 0.2 | L9: 1 | M9: 0 | N9: 0 | P9: no | Q9: 0 | R9: 0 | T9: NSCLC
A10: FearonPrimary | B10: 5 | C10: Implemented criterion boundary | E10: oesophageal | F10: 1.8 | H10: III | I10: 0.5 | J10: 0.5 | L10: 2 | M10: 0.35 | N10: 0.4 | P10: unknown | Q10: 0.15 | R10: 0.15 | T10: unknown
A11: FearonConditional | B11: 2 | C11: Implemented criterion boundary | E11: gastric | F11: 1.8 | H11: IV | I11: 1 | J11: 1 | L11: 3 | M11: 0.7 | N11: 0.8
A12: FearonBMI | B12: 20 | C12: Implemented criterion boundary | E12: pancreatic | F12: 2 | H12: unknown | I12: 0 | J12: 0 | L12: 4 | M12: 1 | N12: 1.1
A13: PreLower | B13: 1 | C13: PROVISIONAL — review required | E13: hepatobiliary | F13: 2 | L13: unknown | M13: 0 | N13: 0
A14: PreUpper | B14: 5 | C14: PROVISIONAL — review required | E14: head and neck | F14: 1.6
A15: AgeThreshold | B15: 55 | C15: Simulation assumption | E15: breast | F15: 1
A16: CategoryLowUpper | B16: -0.84729786 | C16: Internal category boundary | E16: prostate | F16: 1
A17: CategoryHighLower | B17: 0.40546511 | C17: Internal category boundary | E17: other solid tumour | F17: 1
A18: WeightMin | B18: 25 | C18: Input validation bound
A19: WeightMax | B19: 160 | C19: Input validation bound
A20: Category3Intercept | B20: -2 | C20: Simulation assumption
A21: Category3Age | B21: 0.25 | C21: Simulation assumption
A22: Category3Loss | B22: 0.13 | C22: Simulation assumption
A23: Category3BMI | B23: 0.45 | C23: Simulation assumption
A24: Category3Cancer | B24: 1 | C24: Simulation assumption
A25: Category6Intercept | B25: -1.45 | C25: Simulation assumption
A26: Category6Age | B26: 0.3 | C26: Simulation assumption
A27: Category6Loss | B27: 0.15 | C27: Simulation assumption
A28: Category6BMI | B28: 0.5 | C28: Simulation assumption
A29: Category6Cancer | B29: 1 | C29: Simulation assumption

Sheet Synthetic Cohort
A1: Generated synthetic cohort
A2: For plausibility review only; counts do not estimate prevalence.
A4: NOT FOR CLINICAL USE. All patients and outputs are synthetic. Category relationships are simulation assumptions, not clinically validated effects. Do not use for diagnosis, prognosis, treatment, patient care, or medical decisions.
A7: patient_id | B7: prediction_date | C7: age | D7: sex | E7: cancer_type | F7: cancer_stage | G7: height_cm | H7: ecog | I7: reduced_appetite | J7: sarcopenia | K7: baseline_bmi | L7: baseline_loss_percent | M7: baseline_cachexia_status | N7: baseline_precachexia_status | O7: outcome_3m_threshold_status | P7: outcome_3m_fearon_classification | Q7: outcome_3m_interval_days | R7: outcome_3m_precachexia | S7: outcome_3m_basis | T7: category_3m | U7: category_3m_basis | V7: category_3m_status | W7: category_3m_target_outcome | X7: outcome_6m_threshold_status | Y7: outcome_6m_fearon_classification | Z7: outcome_6m_interval_days | AA7: outcome_6m_precachexia | AB7: outcome_6m_basis | AC7: category_6m | AD7: category_6m_basis | AE7: category_6m_status | AF7: category_6m_target_outcome | AG7: edge_case
A8: SYN-20260820-0001 | B8: 2026-01-15 | C8: 87 | D8: male | E8: gastric | F8: IV | G8: 165.4 | H8: unknown | I8: unknown | J8: no | K8: 40.951254 | M8: unknown | N8: unknown | O8: unknown | P8: FALSE | Q8: 90 | R8: unknown | S8: observed_synthetic_follow_up | T8: withheld | U8: baseline_predictors_only | V8: withheld_missing_required_baseline_predictors | W8: not_defined_pending_clinical_review | X8: unknown | Y8: FALSE | Z8: 181 | AA8: unknown | AB8: observed_synthetic_follow_up | AC8: withheld | AD8: baseline_predictors_only | AE8: withheld_missing_required_baseline_predictors | AF8: not_defined_pending_clinical_review | AG8: unknown_fields
A9: SYN-20260820-0002 | B9: 2026-01-16 | C9: 84 | D9: female | E9: head and neck | F9: III | G9: 167.9 | H9: 2 | I9: no | J9: unknown | K9: 38.109769 | M9: unknown | N9: unknown | O9: no | P9: FALSE | Q9: 90 | R9: no | S9: observed_synthetic_follow_up | T9: withheld | U9: baseline_predictors_only | V9: withheld_missing_required_baseline_predictors | W9: not_defined_pending_clinical_review | X9: unknown | Y9: FALSE | Z9: 181 | AA9: unknown | AB9: observed_synthetic_follow_up | AC9: withheld | AD9: baseline_predictors_only | AE9: withheld_missing_required_baseline_predictors | AF9: not_defined_pending_clinical_review | AG9: insufficient_history
A10: SYN-20260820-0003 | B10: 2026-01-17 | C10: 68 | D10: female | E10: breast | F10: III | G10: 164.5 | H10: 1 | I10: no | J10: no | K10: 23.850851 | L10: -3.0927835 | M10: no | N10: no | O10: no | P10: FALSE | Q10: 90 | R10: no | S10: observed_synthetic_follow_up | T10: low | U10: baseline_predictors_only | V10: research_only_not_clinically_validated | W10: not_defined_pending_clinical_review | X10: unknown | Y10: FALSE | Z10: 181 | AA10: unknown | AB10: observed_synthetic_follow_up | AC10: moderate | AD10: baseline_predictors_only | AE10: research_only_not_clinically_validated | AF10: not_defined_pending_clinical_review | AG10: baseline_weight_gain
A11: SYN-20260820-0004 | B11: 2026-01-18 | C11: 73 | D11: male | E11: head and neck | F11: I | G11: 176.8 | H11: 2 | I11: unknown | J11: unknown | K11: 26.259636 | L11: 0 | M11: no | N11: no | O11: no | P11: FALSE | Q11: 90 | R11: no | S11: observed_synthetic_follow_up | T11: withheld | U11: baseline_predictors_only | V11: withheld_missing_required_baseline_predictors | W11: not_defined_pending_clinical_review | X11: no | Y11: FALSE | Z11: 181 | AA11: no | AB11: observed_synthetic_follow_up | AC11: withheld | AD11: baseline_predictors_only | AE11: withheld_missing_required_baseline_predictors | AF11: not_defined_pending_clinical_review | AG11: baseline_stability
A12: SYN-20260820-0005 | B12: 2026-01-19 | C12: 61 | D12: male | E12: prostate | F12: III | G12: 156.2 | H12: 2 | I12: yes | J12: yes | K12: 23.393709 | L12: 3 | M12: unknown | N12: unknown | O12: unknown | P12: FALSE | Q12: 90 | R12: unknown | S12: observed_synthetic_follow_up | T12: moderate | U12: baseline_predictors_only | V12: research_only_not_clinically_validated | W12: not_defined_pending_clinical_review | X12: unknown | Y12: FALSE | Z12: 181 | AA12: unknown | AB12: observed_synthetic_follow_up | AC12: high | AD12: baseline_predictors_only | AE12: research_only_not_clinically_validated | AF12: not_defined_pending_clinical_review | AG12: limited_loss_with_appetite
A13: SYN-20260820-0006 | B13: 2026-01-20 | C13: 68 | D13: male | E13: oesophageal | F13: I | G13: 178.4 | H13: 2 | I13: no | J13: no | K13: 21.526046 | L13: 6 | M13: yes | N13: no | O13: no | P13: FALSE | Q13: 90 | R13: no | S13: observed_synthetic_follow_up | T13: moderate | U13: baseline_predictors_only | V13: research_only_not_clinically_validated | W13: not_defined_pending_clinical_review | X13: unknown | Y13: FALSE | Z13: 181 | AA13: unknown | AB13: observed_synthetic_follow_up | AC13: high | AD13: baseline_predictors_only | AE13: research_only_not_clinically_validated | AF13: not_defined_pending_clinical_review | AG13: supported_cachexia_pattern
A14: SYN-20260820-0007 | B14: 2026-01-21 | C14: 44 | D14: female | E14: lung | F14: IV | G14: 170 | H14: 3 | I14: yes | J14: no | K14: 20 | L14: 2 | M14: unknown | N14: unknown | O14: yes | P14: FALSE | Q14: 90 | R14: no | S14: observed_synthetic_follow_up | T14: high | U14: baseline_predictors_only | V14: research_only_not_clinically_validated | W14: not_defined_pending_clinical_review | X14: yes | Y14: FALSE | Z14: 181 | AA14: no | AB14: observed_synthetic_follow_up | AC14: high | AD14: baseline_predictors_only | AE14: research_only_not_clinically_validated | AF14: not_defined_pending_clinical_review | AG14: bmi_20_weight_loss_2_boundary
A15: SYN-20260820-0008 | B15: 2026-01-22 | C15: 81 | D15: female | E15: hepatobiliary | F15: III | G15: 164.9 | H15: 3 | I15: yes | J15: no | K15: 24.388046 | L15: 5 | M15: unknown | N15: unknown | O15: yes | P15: FALSE | Q15: 90 | R15: no | S15: observed_synthetic_follow_up | T15: high | U15: baseline_predictors_only | V15: research_only_not_clinically_validated | W15: not_defined_pending_clinical_review | X15: yes | Y15: FALSE | Z15: 181 | AA15: no | AB15: observed_synthetic_follow_up | AC15: high | AD15: baseline_predictors_only | AE15: research_only_not_clinically_validated | AF15: not_defined_pending_clinical_review | AG15: weight_loss_5_boundary
A16: SYN-20260820-0009 | B16: 2026-01-23 | C16: 36 | D16: female | E16: lung | F16: III | G16: 165.1 | H16: 2 | I16: unknown | J16: unknown | K16: 37.191637 | M16: unknown | N16: unknown | O16: no | P16: FALSE | Q16: 90 | R16: no | S16: observed_synthetic_follow_up | T16: withheld | U16: baseline_predictors_only | V16: withheld_missing_required_baseline_predictors | W16: not_defined_pending_clinical_review | X16: unknown | Y16: FALSE | Z16: 181 | AA16: unknown | AB16: observed_synthetic_follow_up | AC16: withheld | AD16: baseline_predictors_only | AE16: withheld_missing_required_baseline_predictors | AF16: not_defined_pending_clinical_review
A17: SYN-20260820-0010 | B17: 2026-01-24 | C17: 54 | D17: female | E17: colorectal | F17: III | G17: 162.3 | H17: 2 | I17: yes | J17: no | K17: 39.030738 | L17: 1.5578472 | M17: no | N17: yes | O17: no | P17: FALSE | Q17: 90 | R17: no | S17: observed_synthetic_follow_up | T17: moderate | U17: baseline_predictors_only | V17: research_only_not_clinically_validated | W17: not_defined_pending_clinical_review | X17: no | Y17: FALSE | Z17: 181 | AA17: no | AB17: observed_synthetic_follow_up | AC17: high | AD17: baseline_predictors_only | AE17: research_only_not_clinically_validated | AF17: not_defined_pending_clinical_review
A18: SYN-20260820-0011 | B18: 2026-01-25 | C18: 74 | D18: unknown | E18: gastric | F18: II | G18: 172.9 | H18: unknown | I18: yes | J18: yes | K18: 21.680642 | L18: 2.021164 | M18: unknown | N18: unknown | O18: no | P18: FALSE | Q18: 90 | R18: unknown | S18: observed_synthetic_follow_up | T18: withheld | U18: baseline_predictors_only | V18: withheld_missing_required_baseline_predictors | W18: not_defined_pending_clinical_review | X18: unknown | Y18: FALSE | Z18: 181 | AA18: unknown | AB18: observed_synthetic_follow_up | AC18: withheld | AD18: baseline_predictors_only | AE18: withheld_missing_required_baseline_predictors | AF18: not_defined_pending_clinical_review
A19: SYN-20260820-0012 | B19: 2026-01-26 | C19: 58 | D19: female | E19: head and neck | F19: III | G19: 167.2 | H19: 1 | I19: no | J19: unknown | K19: 36.687504 | L19: 1.0601763 | M19: no | N19: no | O19: no | P19: FALSE | Q19: 90 | R19: no | S19: observed_synthetic_follow_up | T19: moderate | U19: baseline_predictors_only | V19: research_only_not_clinically_validated | W19: not_defined_pending_clinical_review | X19: unknown | Y19: FALSE | Z19: 181 | AA19: unknown | AB19: observed_synthetic_follow_up | AC19: moderate | AD19: baseline_predictors_only | AE19: research_only_not_clinically_validated | AF19: not_defined_pending_clinical_review
A20: SYN-20260820-0013 | B20: 2026-01-27 | C20: 70 | D20: male | E20: head and neck | F20: III | G20: 180.8 | H20: 2 | I20: yes | J20: yes | K20: 31.093065 | L20: 3.2350505 | M20: unknown | N20: unknown | O20: unknown | P20: FALSE | Q20: 90 | R20: unknown | S20: observed_synthetic_follow_up | T20: high | U20: baseline_predictors_only | V20: research_only_not_clinically_validated | W20: not_defined_pending_clinical_review | X20: yes | Y20: FALSE | Z20: 181 | AA20: no | AB20: observed_synthetic_follow_up | AC20: high | AD20: baseline_predictors_only | AE20: research_only_not_clinically_validated | AF20: not_defined_pending_clinical_review
A21: SYN-20260820-0014 | B21: 2026-01-28 | C21: 45 | D21: male | E21: lung | F21: II | G21: 179.7 | H21: 3 | I21: unknown | J21: unknown | K21: 21.600336 | L21: 2.3176999 | M21: unknown | N21: unknown | O21: unknown | P21: FALSE | Q21: 90 | R21: unknown | S21: observed_synthetic_follow_up | T21: withheld | U21: baseline_predictors_only | V21: withheld_missing_required_baseline_predictors | W21: not_defined_pending_clinical_review | X21: yes | Y21: FALSE | Z21: 181 | AA21: no | AB21: observed_synthetic_follow_up | AC21: withheld | AD21: baseline_predictors_only | AE21: withheld_missing_required_baseline_predictors | AF21: not_defined_pending_clinical_review
A22: SYN-20260820-0015 | B22: 2026-01-29 | C22: 65 | D22: female | E22: prostate | F22: II | G22: 151.9 | H22: 4 | I22: no | J22: no | K22: 26.74874 | L22: 1.6179424 | M22: no | N22: no | O22: no | P22: FALSE | Q22: 90 | R22: no | S22: observed_synthetic_follow_up | T22: moderate | U22: baseline_predictors_only | V22: research_only_not_clinically_validated | W22: not_defined_pending_clinical_review | X22: no | Y22: FALSE | Z22: 181 | AA22: unknown | AB22: observed_synthetic_follow_up | AC22: moderate | AD22: baseline_predictors_only | AE22: research_only_not_clinically_validated | AF22: not_defined_pending_clinical_review
A23: SYN-20260820-0016 | B23: 2026-01-30 | C23: 76 | D23: male | E23: breast | F23: III | G23: 168.8 | H23: 1 | I23: no | J23: no | K23: 29.417648 | L23: 0.37439384 | M23: no | N23: no | O23: no | P23: FALSE | Q23: 90 | R23: no | S23: observed_synthetic_follow_up | T23: low | U23: baseline_predictors_only | V23: research_only_not_clinically_validated | W23: not_defined_pending_clinical_review | X23: no | Y23: FALSE | Z23: 181 | AA23: no | AB23: observed_synthetic_follow_up | AC23: moderate | AD23: baseline_predictors_only | AE23: research_only_not_clinically_validated | AF23: not_defined_pending_clinical_review
A24: SYN-20260820-0017 | B24: 2026-01-31 | C24: 66 | D24: male | E24: pancreatic | F24: IV | G24: 176.8 | H24: 1 | I24: no | J24: no | K24: 28.028769 | L24: 3.2947747 | M24: unknown | N24: unknown | O24: unknown | P24: FALSE | Q24: 89 | R24: unknown | S24: observed_synthetic_follow_up | T24: high | U24: baseline_predictors_only | V24: research_only_not_clinically_validated | W24: not_defined_pending_clinical_review | X24: yes | Y24: FALSE | Z24: 181 | AA24: no | AB24: observed_synthetic_follow_up | AC24: high | AD24: baseline_predictors_only | AE24: research_only_not_clinically_validated | AF24: not_defined_pending_clinical_review
A25: SYN-20260820-0018 | B25: 2026-02-01 | C25: 48 | D25: female | E25: pancreatic | F25: II | G25: 163 | H25: 1 | I25: unknown | J25: no | K25: 25.591102 | L25: 2.6306745 | M25: unknown | N25: unknown | O25: unknown | P25: FALSE | Q25: 89 | R25: unknown | S25: observed_synthetic_follow_up | T25: withheld | U25: baseline_predictors_only | V25: withheld_missing_required_baseline_predictors | W25: not_defined_pending_clinical_review | X25: yes | Y25: FALSE | Z25: 181 | AA25: no | AB25: observed_synthetic_follow_up | AC25: withheld | AD25: baseline_predictors_only | AE25: withheld_missing_required_baseline_predictors | AF25: not_defined_pending_clinical_review
A26: SYN-20260820-0019 | B26: 2026-02-02 | C26: 62 | D26: male | E26: colorectal | F26: III | G26: 176.7 | H26: 1 | I26: no | J26: no | K26: 32.110737 | L26: 1.0364331 | M26: no | N26: no | O26: unknown | P26: FALSE | Q26: 89 | R26: unknown | S26: observed_synthetic_follow_up | T26: moderate | U26: baseline_predictors_only | V26: research_only_not_clinically_validated | W26: not_defined_pending_clinical_review | X26: yes | Y26: FALSE | Z26: 181 | AA26: no | AB26: observed_synthetic_follow_up | AC26: moderate | AD26: baseline_predictors_only | AE26: research_only_not_clinically_validated | AF26: not_defined_pending_clinical_review
A27: SYN-20260820-0020 | B27: 2026-02-03 | C27: 27 | D27: male | E27: lung | F27: III | G27: 179.6 | H27: 1 | I27: yes | J27: no | K27: 21.798627 | L27: 2.3945363 | M27: unknown | N27: unknown | O27: no | P27: FALSE | Q27: 89 | R27: yes | S27: observed_synthetic_follow_up | T27: moderate | U27: baseline_predictors_only | V27: research_only_not_clinically_validated | W27: not_defined_pending_clinical_review | X27: unknown | Y27: FALSE | Z27: 181 | AA27: unknown | AB27: observed_synthetic_follow_up | AC27: high | AD27: baseline_predictors_only | AE27: research_only_not_clinically_validated | AF27: not_defined_pending_clinical_review
A28: SYN-20260820-0021 | B28: 2026-02-04 | C28: 57 | D28: male | E28: gastric | F28: IV | G28: 167.8 | H28: 1 | I28: no | J28: yes | K28: 17.452953 | L28: 3.0021909 | M28: yes | N28: no | O28: no | P28: FALSE | Q28: 89 | R28: no | S28: observed_synthetic_follow_up | T28: high | U28: baseline_predictors_only | V28: research_only_not_clinically_validated | W28: not_defined_pending_clinical_review | X28: yes | Y28: FALSE | Z28: 181 | AA28: no | AB28: observed_synthetic_follow_up | AC28: high | AD28: baseline_predictors_only | AE28: research_only_not_clinically_validated | AF28: not_defined_pending_clinical_review
A29: SYN-20260820-0022 | B29: 2026-02-05 | C29: 44 | D29: male | E29: prostate | F29: II | G29: 171.8 | H29: 1 | I29: yes | J29: unknown | K29: 33.413247 | L29: 0.76773694 | M29: no | N29: no | O29: no | P29: FALSE | Q29: 89 | R29: no | S29: observed_synthetic_follow_up | T29: low | U29: baseline_predictors_only | V29: research_only_not_clinically_validated | W29: not_defined_pending_clinical_review | X29: no | Y29: FALSE | Z29: 181 | AA29: no | AB29: observed_synthetic_follow_up | AC29: moderate | AD29: baseline_predictors_only | AE29: research_only_not_clinically_validated | AF29: not_defined_pending_clinical_review
A30: SYN-20260820-0023 | B30: 2026-02-06 | C30: 84 | D30: male | E30: lung | F30: III | G30: 175.5 | H30: 2 | I30: yes | J30: no | K30: 15.495978 | L30: 2.7110767 | M30: yes | N30: no | O30: yes | P30: FALSE | Q30: 89 | R30: no | S30: observed_synthetic_follow_up | T30: high | U30: baseline_predictors_only | V30: research_only_not_clinically_validated | W30: not_defined_pending_clinical_review | X30: yes | Y30: FALSE | Z30: 181 | AA30: no | AB30: observed_synthetic_follow_up | AC30: high | AD30: baseline_predictors_only | AE30: research_only_not_clinically_validated | AF30: not_defined_pending_clinical_review
... A39: SYN-20260820-0032 | B39: 2026-02-15 | C39: 50 | D39: male | E39: breast | F39: II | G39: 170.1 | H39: 2 | I39: yes | J39: no | K39: 17.85926 | L39: 0.63074497 | M39: no | N39: no | O39: no | P39: FALSE | Q39: 89 | R39: no | S39: observed_synthetic_follow_up | T39: moderate | U39: baseline_predictors_only | V39: research_only_not_clinically_validated | W39: not_defined_pending_clinical_review | X39: no | Y39: FALSE | Z39: 181 | AA39: no | AB39: observed_synthetic_follow_up | AC39: high | AD39: baseline_predictors_only | AE39: research_only_not_clinically_validated | AF39: not_defined_pending_clinical_review
A40: SYN-20260820-0033 | B40: 2026-02-16 | C40: 60 | D40: female | E40: pancreatic | F40: III | G40: 161.1 | H40: unknown | I40: yes | J40: no | K40: 40.295593 | L40: 2.6556086 | M40: unknown | N40: unknown | O40: unknown | P40: FALSE | Q40: 89 | R40: unknown | S40: observed_synthetic_follow_up | T40: withheld | U40: baseline_predictors_only | V40: withheld_missing_required_baseline_predictors | W40: not_defined_pending_clinical_review | X40: unknown | Y40: FALSE | Z40: 181 | AA40: unknown | AB40: observed_synthetic_follow_up | AC40: withheld | AD40: baseline_predictors_only | AE40: withheld_missing_required_baseline_predictors | AF40: not_defined_pending_clinical_review
A41: SYN-20260820-0034 | B41: 2026-02-17 | C41: 57 | D41: female | E41: other solid tumour | F41: III | G41: 151.9 | H41: 1 | I41: yes | J41: no | K41: 34.412907 | L41: 0.77973684 | M41: no | N41: no | O41: no | P41: FALSE | Q41: 89 | R41: no | S41: observed_synthetic_follow_up | T41: moderate | U41: baseline_predictors_only | V41: research_only_not_clinically_validated | W41: not_defined_pending_clinical_review | X41: no | Y41: FALSE | Z41: 181 | AA41: no | AB41: observed_synthetic_follow_up | AC41: moderate | AD41: baseline_predictors_only | AE41: research_only_not_clinically_validated | AF41: not_defined_pending_clinical_review
A42: SYN-20260820-0035 | B42: 2026-02-18 | C42: 37 | D42: female | E42: gastric | F42: IV | G42: 162.7 | H42: 2 | I42: yes | J42: unknown | K42: 30.443926 | L42: 3.9601011 | M42: unknown | N42: unknown | O42: unknown | P42: FALSE | Q42: 89 | R42: unknown | S42: observed_synthetic_follow_up | T42: high | U42: baseline_predictors_only | V42: research_only_not_clinically_validated | W42: not_defined_pending_clinical_review | X42: yes | Y42: FALSE | Z42: 181 | AA42: no | AB42: observed_synthetic_follow_up | AC42: high | AD42: baseline_predictors_only | AE42: research_only_not_clinically_validated | AF42: not_defined_pending_clinical_review
A43: SYN-20260820-0036 | B43: 2026-02-19 | C43: 66 | D43: female | E43: breast | F43: IV | G43: 160.7 | H43: 1 | I43: no | J43: unknown | K43: 41.178742 | L43: 0.52105258 | M43: no | N43: no | O43: no | P43: FALSE | Q43: 89 | R43: no | S43: observed_synthetic_follow_up | T43: moderate | U43: baseline_predictors_only | V43: research_only_not_clinically_validated | W43: not_defined_pending_clinical_review | X43: unknown | Y43: FALSE | Z43: 181 | AA43: unknown | AB43: observed_synthetic_follow_up | AC43: moderate | AD43: baseline_predictors_only | AE43: research_only_not_clinically_validated | AF43: not_defined_pending_clinical_review
A44: SYN-20260820-0037 | B44: 2026-02-20 | C44: 58 | D44: female | E44: hepatobiliary | F44: I | G44: 165.2 | H44: 2 | I44: yes | J44: no | K44: 19.42066 | L44: 2.5949681 | M44: yes | N44: no | O44: no | P44: FALSE | Q44: 89 | R44: yes | S44: observed_synthetic_follow_up | T44: high | U44: baseline_predictors_only | V44: research_only_not_clinically_validated | W44: not_defined_pending_clinical_review | X44: yes | Y44: FALSE | Z44: 181 | AA44: no | AB44: observed_synthetic_follow_up | AC44: high | AD44: baseline_predictors_only | AE44: research_only_not_clinically_validated | AF44: not_defined_pending_clinical_review
A45: SYN-20260820-0038 | B45: 2026-02-21 | C45: 53 | D45: male | E45: gastric | F45: IV | G45: 178.9 | H45: 2 | I45: no | J45: no | K45: 30.684379 | L45: 3.6430891 | M45: unknown | N45: unknown | O45: unknown | P45: FALSE | Q45: 89 | R45: unknown | S45: observed_synthetic_follow_up | T45: high | U45: baseline_predictors_only | V45: research_only_not_clinically_validated | W45: not_defined_pending_clinical_review | X45: yes | Y45: FALSE | Z45: 181 | AA45: no | AB45: observed_synthetic_follow_up | AC45: high | AD45: baseline_predictors_only | AE45: research_only_not_clinically_validated | AF45: not_defined_pending_clinical_review
A46: SYN-20260820-0039 | B46: 2026-02-22 | C46: 75 | D46: male | E46: other solid tumour | F46: II | G46: 177 | H46: 3 | I46: no | J46: unknown | K46: 15.932203 | L46: 1.3323318 | M46: no | N46: no | O46: no | P46: FALSE | Q46: 89 | R46: no | S46: observed_synthetic_follow_up | T46: moderate | U46: baseline_predictors_only | V46: research_only_not_clinically_validated | W46: not_defined_pending_clinical_review | X46: no | Y46: FALSE | Z46: 181 | AA46: no | AB46: observed_synthetic_follow_up | AC46: high | AD46: baseline_predictors_only | AE46: research_only_not_clinically_validated | AF46: not_defined_pending_clinical_review
A47: SYN-20260820-0040 | B47: 2026-02-23 | C47: 66 | D47: male | E47: head and neck | F47: IV | G47: 182.2 | H47: 0 | I47: yes | J47: unknown | K47: 29.197357 | L47: 2.2677086 | M47: unknown | N47: unknown | O47: unknown | P47: FALSE | Q47: 89 | R47: unknown | S47: observed_synthetic_follow_up | T47: high | U47: baseline_predictors_only | V47: research_only_not_clinically_validated | W47: not_defined_pending_clinical_review | X47: yes | Y47: FALSE | Z47: 181 | AA47: no | AB47: observed_synthetic_follow_up | AC47: high | AD47: baseline_predictors_only | AE47: research_only_not_clinically_validated | AF47: not_defined_pending_clinical_review
A48: SYN-20260820-0041 | B48: 2026-02-24 | C48: 82 | D48: female | E48: lung | F48: IV | G48: 161.5 | H48: 1 | I48: yes | J48: no | K48: 27.015691 | L48: 2.7989295 | M48: unknown | N48: unknown | O48: unknown | P48: FALSE | Q48: 89 | R48: unknown | S48: observed_synthetic_follow_up | T48: high | U48: baseline_predictors_only | V48: research_only_not_clinically_validated | W48: not_defined_pending_clinical_review | X48: unknown | Y48: FALSE | Z48: 181 | AA48: unknown | AB48: observed_synthetic_follow_up | AC48: high | AD48: baseline_predictors_only | AE48: research_only_not_clinically_validated | AF48: not_defined_pending_clinical_review
A49: SYN-20260820-0042 | B49: 2026-02-25 | C49: 51 | D49: female | E49: colorectal | F49: IV | G49: 170 | H49: 1 | I49: no | J49: unknown | K49: 28.470242 | L49: 2.1420076 | M49: unknown | N49: unknown | O49: unknown | P49: FALSE | Q49: 89 | R49: unknown | S49: observed_synthetic_follow_up | T49: moderate | U49: baseline_predictors_only | V49: research_only_not_clinically_validated | W49: not_defined_pending_clinical_review | X49: unknown | Y49: FALSE | Z49: 181 | AA49: unknown | AB49: observed_synthetic_follow_up | AC49: moderate | AD49: baseline_predictors_only | AE49: research_only_not_clinically_validated | AF49: not_defined_pending_clinical_review
A50: SYN-20260820-0043 | B50: 2026-02-26 | C50: 45 | D50: male | E50: lung | F50: III | G50: 178.5 | H50: 2 | I50: yes | J50: yes | K50: 25.359163 | L50: 1.9500771 | M50: no | N50: yes | O50: no | P50: FALSE | Q50: 89 | R50: no | S50: observed_synthetic_follow_up | T50: high | U50: baseline_predictors_only | V50: research_only_not_clinically_validated | W50: not_defined_pending_clinical_review | X50: no | Y50: FALSE | Z50: 181 | AA50: no | AB50: observed_synthetic_follow_up | AC50: high | AD50: baseline_predictors_only | AE50: research_only_not_clinically_validated | AF50: not_defined_pending_clinical_review
A51: SYN-20260820-0044 | B51: 2026-02-27 | C51: 70 | D51: male | E51: hepatobiliary | F51: I | G51: 181.1 | H51: unknown | I51: no | J51: no | K51: 29.029908 | L51: 1.2958739 | M51: no | N51: no | O51: no | P51: FALSE | Q51: 89 | R51: no | S51: observed_synthetic_follow_up | T51: withheld | U51: baseline_predictors_only | V51: withheld_missing_required_baseline_predictors | W51: not_defined_pending_clinical_review | X51: unknown | Y51: FALSE | Z51: 181 | AA51: unknown | AB51: observed_synthetic_follow_up | AC51: withheld | AD51: baseline_predictors_only | AE51: withheld_missing_required_baseline_predictors | AF51: not_defined_pending_clinical_review
...

Sheet Data Dictionary
A1: Data dictionary
A2: Units, values, and unknown behavior.
A4: NOT FOR CLINICAL USE. All patients and outputs are synthetic. Category relationships are simulation assumptions, not clinically validated effects. Do not use for diagnosis, prognosis, treatment, patient care, or medical decisions.
A8: Field | B8: Unit/type | C8: Definition
A9: patient_id | B9: text | C9: SYN-* synthetic identifier
A10: prediction_date | B10: date | C10: Explicit predictor cutoff
A11: age | B11: years | C11: 18–95
A12: sex | B12: category | C12: female / male / unknown; descriptive and unused in category
A13: cancer_type | B13: category | C13: Synthetic adult solid-tumour stratifier pending review
A14: cancer_subtype | B14: category | C14: Lung description or not applicable; unused in category
A15: cancer_stage | B15: category | C15: I / II / III / IV / unknown
A16: height_cm | B16: cm | C16: 140–200 or blank/unknown
A17: weights | B17: kg + date | C17: 25–160 kg; multiple dated rows
A18: ecog | B18: category | C18: 0–4 / unknown
A19: reduced_appetite | B19: tri-state | C19: yes / no / unknown
... A27: illustrative_simulation_3m/6m | B27: ordinal category | C27: low / moderate / high or withheld; baseline predictors only; target outcome not defined pending clinical review

Sheet Clinical Review
A1: Clinical review decisions
A2: No approval has been received. Record decisions explicitly; blank is not approval.
A4: NOT FOR CLINICAL USE. All patients and outputs are synthetic. Category relationships are simulation assumptions, not clinically validated effects. Do not use for diagnosis, prognosis, treatment, patient care, or medical decisions.
A7: ID | B7: Question | C7: Owner | D7: Status | E7: Decision | F7: Rationale | G7: Effective date
A8: CLIN-001 | B8: Confirm/revise predictor ranges and distributions | C8: Clinical review | D8: pending
A9: CLIN-002 | B9: Confirm stage/ECOG/appetite simulation relationships | C9: Clinical review | D9: pending
A10: CLIN-003 | B10: Approve/reject/revise provisional pre-cachexia rule | C10: Clinical review | D10: pending
A11: CLIN-004 | B11: Confirm Fearon implementation and unknown behavior | C11: Clinical review | D11: pending
A12: CLIN-005 | B12: Confirm outcome selection and inclusive boundaries | C12: Clinical review | D12: pending
A13: CLIN-006 | B13: Confirm sarcopenia representation | C13: Clinical review | D13: pending
A14: CLIN-007 | B14: Define eligibility and inclusion criteria | C14: Clinical review | D14: pending
A15: CLIN-008 | B15: Confirm dated follow-up appetite evidence and binary simplification | C15: Clinical review | D15: pending
A16: CLIN-009 | B16: Define the target outcome or estimand for illustrative categories | C16: Clinical review | D16: pending
A17: UX-001 | B17: Identify clinically misleading wording or presentation | C17: Clinical review | D17: pending
